Workbook

Sheet Guide
A1: IRB Infrastructure Developers Ltd — Financial Spreading & Ratio Analysis Model
A2: Consolidated, ₹ crore, FY2022–FY2026 actuals with FY2027E–FY2031E projections. Prepared 19 Oct 2026.
A4: TABS
A5: Inputs | B5: Spread of P&L, balance sheet and cash-flow items for 5 years, plus parameters (days, TNW switch, benchmark thresholds).
A6: Ratios | B6: Historical DSCR, TOL/TNW, current ratio, ICR, working capital cycle and supporting credit metrics, with benchmark flags.
A7: Projections | B7: Five-year driver-based projection: P&L, debt schedule, balance sheet, cash flow, ratios and integrity checks.
A8: Sensitivity | B8: Four live grids on FY2027E DSCR, ICR and TOL/TNW (revenue growth, margin, interest rate, additional borrowing).
A10: COLOUR LEGEND
A11: Blue text | B11: Hard-coded input or assumption — safe to overwrite.
A12: Black text | B12: Formula — do not overwrite.
A13: Green text | B13: Link to another sheet.
A14: Yellow fill | B14: Key assumption the user is expected to review (parameters; projection drivers).
A15: Red / green fill | B15: Benchmark breached / met (conditional formatting; thresholds on Inputs rows 7–10).
A17: RATIO DEFINITIONS
A18: DSCR | B18: (PAT – exceptional items + depreciation + finance cost) ÷ (finance cost + prior-year current portion of long-term debt). FY2022 is n.a. (no FY2021 spread).
A19: TOL / TNW | B19: Total outside liabilities ÷ tangible net worth. TNW = net worth (incl. minority) less intangibles × switch (Inputs!B6; default 0 = concession rights treated as tangible). A strict memo line is shown on Ratios.
A20: Current ratio | B20: Total current assets ÷ total current liabilities (current liabilities include current maturities of debt).
A21: ICR | B21: (PBT before exceptional items + finance cost) ÷ finance cost. EBITDA/interest is shown as a memo.
A22: Working capital cycle | B22: Debtor days (receivables ÷ sales) + inventory days – creditor days (both ÷ operating expenditure), on year-end balances.
A24: DATA SOURCES & NOTES
A25: P&L | B25: Consolidated annual results as published by Anand Rathi (anandrathi.com/stocks/irb-infradeveloper/financial-results/200048); FY2026 results announced May 2026.
A26: Balance sheet & cash flow | B26: S&P Global Market Intelligence via StockAnalysis.com (NSE:IRB), published in ₹ million and converted to ₹ crore (÷ 10). Total assets FY2026 = ₹54,054 cr here vs ₹53,998 cr on Screener — vendor classification differs slightly.
A27: Balancing lines | B27: Other current assets, other non-current assets, other current liabilities and other non-current liabilities are derived so that each subtotal ties to the vendor's reported totals. Other non-current liabilities (~₹11,500 cr) sit inside TOL; check their composition in the annual report notes before relying on TOL/TNW.
A28: FY2025 exceptional gain | B28: FY2025 PAT of ₹6,618 cr includes a ₹5,804 cr one-off gain; ratios strip it out (adjusted PAT / PBT).
A29: Projections | B29: Base-case drivers are illustrative, not management guidance or a forecast. Exceptional items are assumed nil; PPE is held flat; new borrowing is an input chosen so cash stays non-negative.
A30: Benchmarks | B30: DSCR ≥ 1.20x, current ratio ≥ 1.00x, TOL/TNW ≤ 3.00x, ICR ≥ 1.50x are placeholder thresholds, not IRB's actual covenants.
A31: Re-use | B31: To analyse another borrower, overwrite the blue cells on Inputs (including the four balancing lines) and the projection drivers; everything else recalculates.

Sheet Inputs
A1: IRB Infrastructure Developers Ltd — Financial Spreading (Consolidated)
A2: ₹ crore, fiscal years ended 31 March. Blue = hard-coded input (overwrite to re-use for another borrower); black = formula.
A4: PARAMETERS & BENCHMARKS
A5: Days in year (for working-capital days) | B5: 365 | G5: Assumption
A6: Deduct intangibles (concession rights) from TNW? 1 = Yes, 0 = No | B6: 0 | G6: Assumption: default 0 because toll/BOT concession rights are the revenue-generating asset. Set 1 for the strict view.
A7: Benchmark: minimum DSCR (x) | B7: 1.2 | G7: Illustrative threshold — replace with sanction/covenant terms
A8: Benchmark: minimum current ratio (x) | B8: 1 | G8: Illustrative threshold — replace with sanction/covenant terms
A9: Benchmark: maximum TOL/TNW (x) | B9: 3 | G9: Illustrative threshold — replace with sanction/covenant terms
A10: Benchmark: minimum ICR (x) | B10: 1.5 | G10: Illustrative threshold — replace with sanction/covenant terms
A13: ₹ crore | B13: FY2022 | C13: FY2023 | D13: FY2024 | E13: FY2025 | F13: FY2026 | G13: Source / note
A14: INCOME STATEMENT
A15: Net sales / revenue from operations | B15: 5803.7 | C15: 6401.64 | D15: 7409 | E15: 7613.47 | F15: 7648.15 | G15: Consolidated results, Anand Rathi (anandrathi.com)
A16: Total operating expenditure | B16: 3006.2 | C16: 3172.61 | D16: 4077.21 | E16: 4007.62 | F16: 3666.33 | G16: Consolidated results, Anand Rathi (anandrathi.com)
A17: EBITDA (PBIDT excl. other income) | B17: =B15-B16 -> 2797.5 | C17: =C15-C16 -> 3229.03 | D17: =D15-D16 -> 3331.79 | E17: =E15-E16 -> 3605.85 | F17: =F15-F16 -> 3981.82
A18: Other income | B18: 551.75 | C18: 301.67 | D18: 792.76 | E18: 418.08 | F18: 205.83 | G18: Consolidated results, Anand Rathi (anandrathi.com)
A19: Finance cost (interest) | B19: 1890.62 | C19: 1514.63 | D19: 1863.32 | E19: 1791.94 | F19: 1755.15 | G19: Consolidated results, Anand Rathi (anandrathi.com)
A20: Exceptional items (gain + / loss –) | B20: 0 | C20: 0 | D20: 0 | E20: 5804.13 | F20: -42.65 | G20: FY25 = ₹5,804 cr one-off gain (non-cash, InvIT-related); FY26 = loss
A21: Depreciation & amortisation | B21: 682.77 | C21: 832.12 | D21: 994.95 | E21: 1037.63 | F21: 1142.04 | G21: Consolidated results, Anand Rathi (anandrathi.com)
A22: Profit before tax | B22: =B17+B18-B19+B20-B21 -> 775.86 | C22: =C17+C18-C19+C20-C21 -> 1183.95 | D22: =D17+D18-D19+D20-D21 -> 1266.28 | E22: =E17+E18-E19+E20-E21 -> 6998.49 | F22: =F17+F18-F19+F20-F21 -> 1247.81
A23: Tax expense | B23: 188.23 | C23: 356.94 | D23: 345.62 | E23: 380.71 | F23: 397.46 | G23: Consolidated results, Anand Rathi (anandrathi.com)
A24: Profit after tax (before minority interest) | B24: =B22-B23 -> 587.63 | C24: =C22-C23 -> 827.01 | D24: =D22-D23 -> 920.66 | E24: =E22-E23 -> 6617.78 | F24: =F22-F23 -> 850.35
A25: Reported PAT (for tie-out) | B25: 587.62 | C25: 827.02 | D25: 920.67 | E25: 6617.79 | F25: 850.36 | G25: Consolidated results, Anand Rathi (anandrathi.com)
A26: Check: computed PAT – reported PAT (rounding only) | B26: =B24-B25 -> 0.01 | C26: =C24-C25 -> -0.01 | D26: =D24-D25 -> -0.01 | E26: =E24-E25 -> -0.01 | F26: =F24-F25 -> -0.01
A28: BALANCE SHEET — ASSETS
A29: Cash & cash equivalents | B29: 52.98 | C29: 300.6 | D29: 232.7 | E29: 1859.5 | F29: 346.3 | G29: S&P Global via StockAnalysis (₹ mn ÷ 10)
A30: Short-term investments / trading securities | B30: 463.5 | C30: 195.7 | D30: 265 | E30: 16.72 | F30: 181.2 | G30: S&P Global via StockAnalysis (₹ mn ÷ 10)
A31: Trade receivables | B31: 1512.9 | C31: 2300.1 | D31: 1317.6 | E31: 994.2 | F31: 1075.5 | G31: S&P Global via StockAnalysis (₹ mn ÷ 10)
A32: Other receivables | B32: 428.2 | C32: 702 | D32: 710.7 | E32: 699.8 | F32: 706.2 | G32: S&P Global via StockAnalysis (₹ mn ÷ 10)
A33: Inventory | B33: 317.5 | C33: 299 | D33: 293.1 | E33: 338.6 | F33: 367 | G33: S&P Global via StockAnalysis (₹ mn ÷ 10)
A34: Prepaid expenses | B34: 46.32 | C34: 16.81 | D34: 4.98 | E34: 4.07 | F34: 9.9 | G34: S&P Global via StockAnalysis (₹ mn ÷ 10)
A35: Other current assets (balancing to reported total) | B35: 2306.1 | C35: 3150.89 | D35: 2015.32 | E35: 1995.81 | F35: 1995.6 | G35: Derived: reported total current assets less the lines above
A36: Total current assets | B36: =SUM(B29:B35) -> 5127.5 | C36: =SUM(C29:C35) -> 6965.1 | D36: =SUM(D29:D35) -> 4839.4 | E36: =SUM(E29:E35) -> 5908.7 | F36: =SUM(F29:F35) -> 4681.7
A37: Property, plant & equipment | B37: 984.2 | C37: 950 | D37: 922 | E37: 986.3 | F37: 946.1 | G37: S&P Global via StockAnalysis (₹ mn ÷ 10)
A38: Intangibles incl. goodwill (concession rights) | B38: 26349.4 | C38: 25537.6 | D38: 24599.4 | E38: 23630.4 | F38: 22953.8 | G38: S&P Global via StockAnalysis (₹ mn ÷ 10); other intangibles + goodwill
A39: Long-term investments | B39: 4440.7 | C39: 4945.2 | D39: 9377 | E39: 17080.6 | F39: 19147 | G39: S&P Global via StockAnalysis (₹ mn ÷ 10)
A40: Other non-current assets (balancing to reported total) | B40: 5664.8 | C40: 4368.3 | D40: 5182.5 | E40: 6290 | F40: 6325 | G40: Derived: reported total assets less lines above
A41: Total assets | B41: =B36+B37+B38+B39+B40 -> 42566.6 | C41: =C36+C37+C38+C39+C40 -> 42766.2 | D41: =D36+D37+D38+D39+D40 -> 44920.3 | E41: =E36+E37+E38+E39+E40 -> 53896 | F41: =F36+F37+F38+F39+F40 -> 54053.6
A43: BALANCE SHEET — LIABILITIES & EQUITY
A44: Trade payables | B44: 381.7 | C44: 502.2 | D44: 675.7 | E44: 521.8 | F44: 256.8 | G44: S&P Global via StockAnalysis (₹ mn ÷ 10)
A45: Accrued expenses | B45: 83.35 | C45: 151.3 | D45: 306.4 | E45: 181.5 | F45: 170.1 | G45: S&P Global via StockAnalysis (₹ mn ÷ 10)
...

Sheet Ratios
A1: IRB Infrastructure Developers Ltd — Ratio Analysis (Historical)
A2: All figures link to the Inputs tab. Green = link to another sheet, black = calculation. Ratios in x unless stated.
A4: ₹ crore / ratio | B4: FY2022 | C4: FY2023 | D4: FY2024 | E4: FY2025 | F4: FY2026 | G4: Definition
A5: A. DEBT SERVICE COVERAGE (DSCR)
A6: Profit after tax | B6: =Inputs!B24 -> 587.63 | C6: =Inputs!C24 -> 827.01 | D6: =Inputs!D24 -> 920.66 | E6: =Inputs!E24 -> 6617.78 | F6: =Inputs!F24 -> 850.35
A7: Less: exceptional items (non-recurring) | B7: =Inputs!B20 -> 0 | C7: =Inputs!C20 -> 0 | D7: =Inputs!D20 -> 0 | E7: =Inputs!E20 -> 5804.13 | F7: =Inputs!F20 -> -42.65
A8: Adjusted PAT | B8: =B6-B7 -> 587.63 | C8: =C6-C7 -> 827.01 | D8: =D6-D7 -> 920.66 | E8: =E6-E7 -> 813.65 | F8: =F6-F7 -> 893
A9: Add: depreciation & amortisation | B9: =Inputs!B21 -> 682.77 | C9: =Inputs!C21 -> 832.12 | D9: =Inputs!D21 -> 994.95 | E9: =Inputs!E21 -> 1037.63 | F9: =Inputs!F21 -> 1142.04
A10: Add: finance cost | B10: =Inputs!B19 -> 1890.62 | C10: =Inputs!C19 -> 1514.63 | D10: =Inputs!D19 -> 1863.32 | E10: =Inputs!E19 -> 1791.94 | F10: =Inputs!F19 -> 1755.15
A11: Cash accruals available for debt service | B11: =B8+B9+B10 -> 3161.02 | C11: =C8+C9+C10 -> 3173.76 | D11: =D8+D9+D10 -> 3778.93 | E11: =E8+E9+E10 -> 3643.22 | F11: =F8+F9+F10 -> 3790.19 | G11: (PAT – exceptional items) + depreciation + finance cost
A12: Scheduled principal (prior-year current portion of LT debt) | B12: n.a. | C12: =Inputs!B47 -> 636.49 | D12: =Inputs!C47 -> 1156.86 | E12: =Inputs!D47 -> 1209.99 | F12: =Inputs!E47 -> 1453.42 | G12: Current maturities of LT debt at the start of the year (FY22 n.a. — FY21 balance sheet not spread)
A13: Debt service (interest + scheduled principal) | B13: n.a. | C13: =C10+C12 -> 2151.12 | D13: =D10+D12 -> 3020.18 | E13: =E10+E12 -> 3001.93 | F13: =F10+F12 -> 3208.57
A14: DSCR (x) | B14: n.a. | C14: =IF(C13>0,C11/C13,"n.a.") -> 1.4753989 | D14: =IF(D13>0,D11/D13,"n.a.") -> 1.2512267 | E14: =IF(E13>0,E11/E13,"n.a.") -> 1.2136259 | F14: =IF(F13>0,F11/F13,"n.a.") -> 1.1812708 | G14: Cash accruals ÷ (interest + scheduled principal)
A15: Memo: reported cash flow from operations | B15: =Inputs!B64 -> 364.1 | C15: =Inputs!C64 -> 1764.1 | D15: =Inputs!D64 -> 4053.8 | E15: =Inputs!E64 -> 1971.2 | F15: =Inputs!F64 -> 2098
A16: Memo: cash interest paid + LT debt repaid | B16: =Inputs!B68+Inputs!B69 -> 4951.4 | C16: =Inputs!C68+Inputs!C69 -> 2846.6 | D16: =Inputs!D68+Inputs!D69 -> 5751.8 | E16: =Inputs!E68+Inputs!E69 -> 2617.9 | F16: =Inputs!F68+Inputs!F69 -> 2783
A17: Memo: cash-based DSCR (x) | B17: =IF(B16>0,B15/B16,"n.a.") -> 0.073534758 | C17: =IF(C16>0,C15/C16,"n.a.") -> 0.61972177 | D17: =IF(D16>0,D15/D16,"n.a.") -> 0.70478807 | E17: =IF(E16>0,E15/E16,"n.a.") -> 0.75296994 | F17: =IF(F16>0,F15/F16,"n.a.") -> 0.75386274 | G17: Reported CFO ÷ (cash interest + LT debt repaid). CFO is shown before interest in the S&P presentation
A19: B. TOL / TNW
A20: Total outside liabilities (TOL) | B20: =Inputs!B52 -> 30001 | C20: =Inputs!C52 -> 29387.3 | D20: =Inputs!D52 -> 31175.8 | E20: =Inputs!E52 -> 34069.4 | F20: =Inputs!F52 -> 33104.8
A21: Net worth (incl. minority interest) | B21: =Inputs!B55 -> 12565.6 | C21: =Inputs!C55 -> 13378.9 | D21: =Inputs!D55 -> 13744.5 | E21: =Inputs!E55 -> 19826.6 | F21: =Inputs!F55 -> 20948.8
A22: Less: intangibles deducted (per switch on Inputs) | B22: =Inputs!B38*Inputs!$B$6 -> 0 | C22: =Inputs!C38*Inputs!$B$6 -> 0 | D22: =Inputs!D38*Inputs!$B$6 -> 0 | E22: =Inputs!E38*Inputs!$B$6 -> 0 | F22: =Inputs!F38*Inputs!$B$6 -> 0
A23: Tangible net worth (TNW) | B23: =B21-B22 -> 12565.6 | C23: =C21-C22 -> 13378.9 | D23: =D21-D22 -> 13744.5 | E23: =E21-E22 -> 19826.6 | F23: =F21-F22 -> 20948.8
A24: TOL / TNW (x) | B24: =IF(B23>0,B20/B23,"n.m.") -> 2.3875501 | C24: =IF(C23>0,C20/C23,"n.m.") -> 2.1965408 | D24: =IF(D23>0,D20/D23,"n.m.") -> 2.2682382 | E24: =IF(E23>0,E20/E23,"n.m.") -> 1.7183683 | F24: =IF(F23>0,F20/F23,"n.m.") -> 1.5802719 | G24: Total outside liabilities ÷ tangible net worth; "n.m." where TNW ≤ 0
A25: Memo: TNW with all intangibles deducted | B25: =B21-Inputs!B38 -> -13783.8 | C25: =C21-Inputs!C38 -> -12158.7 | D25: =D21-Inputs!D38 -> -10854.9 | E25: =E21-Inputs!E38 -> -3803.8 | F25: =F21-Inputs!F38 -> -2005
A26: Memo: TOL / TNW — strict basis (x) | B26: =IF(B25>0,B20/B25,"n.m.") -> n.m. | C26: =IF(C25>0,C20/C25,"n.m.") -> n.m. | D26: =IF(D25>0,D20/D25,"n.m.") -> n.m. | E26: =IF(E25>0,E20/E25,"n.m.") -> n.m. | F26: =IF(F25>0,F20/F25,"n.m.") -> n.m.
A27: Memo: total debt / net worth (x) | B27: =Inputs!B60/B21 -> 1.329264 | C27: =Inputs!C60/C21 -> 1.2518376 | D27: =Inputs!D60/D21 -> 1.357153 | E27: =Inputs!E60/E21 -> 1.0389729 | F27: =Inputs!F60/F21 -> 0.95600034
A29: C. LIQUIDITY
A30: Total current assets | B30: =Inputs!B36 -> 5127.5 | C30: =Inputs!C36 -> 6965.1 | D30: =Inputs!D36 -> 4839.4 | E30: =Inputs!E36 -> 5908.7 | F30: =Inputs!F36 -> 4681.7
A31: Total current liabilities | B31: =Inputs!B49 -> 2877.4 | C31: =Inputs!C49 -> 4304.5 | D31: =Inputs!D49 -> 3909.3 | E31: =Inputs!E49 -> 3746.2 | F31: =Inputs!F49 -> 3779.6
A32: Current ratio (x) | B32: =B30/B31 -> 1.7819907 | C32: =C30/C31 -> 1.6180973 | D32: =D30/D31 -> 1.2379198 | E32: =E30/E31 -> 1.5772516 | F32: =F30/F31 -> 1.2386761 | G32: Current assets ÷ current liabilities
A33: Net working capital | B33: =B30-B31 -> 2250.1 | C33: =C30-C31 -> 2660.6 | D33: =D30-D31 -> 930.1 | E33: =E30-E31 -> 2162.5 | F33: =F30-F31 -> 902.1
A35: D. INTEREST COVERAGE (ICR)
A36: Profit before tax | B36: =Inputs!B22 -> 775.86 | C36: =Inputs!C22 -> 1183.95 | D36: =Inputs!D22 -> 1266.28 | E36: =Inputs!E22 -> 6998.49 | F36: =Inputs!F22 -> 1247.81
A37: PBT before exceptional items | B37: =B36-Inputs!B20 -> 775.86 | C37: =C36-Inputs!C20 -> 1183.95 | D37: =D36-Inputs!D20 -> 1266.28 | E37: =E36-Inputs!E20 -> 1194.36 | F37: =F36-Inputs!F20 -> 1290.46
A38: PBIT before exceptional items (PBT + interest) | B38: =B37+B10 -> 2666.48 | C38: =C37+C10 -> 2698.58 | D38: =D37+D10 -> 3129.6 | E38: =E37+E10 -> 2986.3 | F38: =F37+F10 -> 3045.61
A39: ICR (x) | B39: =B38/B10 -> 1.4103733 | C39: =C38/C10 -> 1.7816761 | D39: =D38/D10 -> 1.6795827 | E39: =E38/E10 -> 1.6665179 | F39: =F38/F10 -> 1.735242 | G39: (PBT before exceptional items + interest) ÷ interest
A40: EBITDA | B40: =Inputs!B17 -> 2797.5 | C40: =Inputs!C17 -> 3229.03 | D40: =Inputs!D17 -> 3331.79 | E40: =Inputs!E17 -> 3605.85 | F40: =Inputs!F17 -> 3981.82
A41: Memo: EBITDA / interest (x) | B41: =B40/B10 -> 1.4796733 | C41: =C40/C10 -> 2.1318936 | D41: =D40/D10 -> 1.7880933 | E41: =E40/E10 -> 2.0122605 | F41: =F40/F10 -> 2.2686494
A43: E. WORKING CAPITAL CYCLE (days, year-end balances)
A44: Net sales | B44: =Inputs!B15 -> 5803.7 | C44: =Inputs!C15 -> 6401.64 | D44: =Inputs!D15 -> 7409 | E44: =Inputs!E15 -> 7613.47 | F44: =Inputs!F15 -> 7648.15
A45: Operating expenditure | B45: =Inputs!B16 -> 3006.2 | C45: =Inputs!C16 -> 3172.61 | D45: =Inputs!D16 -> 4077.21 | E45: =Inputs!E16 -> 4007.62 | F45: =Inputs!F16 -> 3666.33
...

Sheet Projections
A1: IRB Infrastructure Developers Ltd — Projections FY2027E–FY2031E
A2: ₹ crore. Blue = editable assumption (illustrative base case — replace with management / rating-agency case). Actual columns show historical equivalents of each driver for reference.
B4: Actual | C4: Actual | D4: Actual | E4: Actual | F4: Actual | G4: Projected | H4: Projected | I4: Projected | J4: Projected | K4: Projected
A5: ₹ crore | B5: FY2022 | C5: FY2023 | D5: FY2024 | E5: FY2025 | F5: FY2026 | G5: FY2027E | H5: FY2028E | I5: FY2029E | J5: FY2030E | K5: FY2031E | L5: Assumption / note
A6: KEY ASSUMPTIONS
A7: Revenue growth | C7: =C27/B27-1 -> 0.10302738 | D7: =D27/C27-1 -> 0.15735968 | E7: =E27/D27-1 -> 0.027597517 | F7: =F27/E27-1 -> 0.0045550846 | G7: 0.08 | H7: 0.08 | I7: 0.07 | J7: 0.07 | K7: 0.06 | L7: Illustrative: toll growth offset by lower construction revenue (FY26 reported +0.5%)
A8: EBITDA margin | B8: =B29/B27 -> 0.48202009 | C8: =C29/C27 -> 0.50440668 | D8: =D29/D27 -> 0.44969497 | E8: =E29/E27 -> 0.47361453 | F8: =F29/F27 -> 0.52062525 | G8: 0.52 | H8: 0.52 | I8: 0.52 | J8: 0.52 | K8: 0.52 | L8: Held at ~FY26 level (52.1%)
A9: Other income (% of revenue) | B9: =B30/B27 -> 0.095068663 | C9: =C30/C27 -> 0.047123862 | D9: =D30/D27 -> 0.1069996 | E9: =E30/E27 -> 0.0549132 | F9: =F30/F27 -> 0.026912391 | G9: 0.027 | H9: 0.027 | I9: 0.027 | J9: 0.027 | K9: 0.027 | L9: Held at ~FY26 level (2.7%)
A10: Depreciation & amortisation (% of opening net block) | C10: =C33/(B51+B52) -> 0.030443118 | D10: =D33/(C51+C52) -> 0.03756286 | E10: =E33/(D51+D52) -> 0.040657252 | F10: =F33/(E51+E52) -> 0.046392896 | G10: 0.046 | H10: 0.046 | I10: 0.046 | J10: 0.046 | K10: 0.046 | L10: FY26 = 4.6% of opening PPE + intangibles
A11: Interest rate on average total debt | C11: =C31/AVERAGE(B43,C43) -> 0.090557561 | D11: =D31/AVERAGE(C43,D43) -> 0.10526756 | E11: =E31/AVERAGE(D43,E43) -> 0.091302787 | F11: =F31/AVERAGE(E43,F43) -> 0.086404492 | G11: 0.086 | H11: 0.086 | I11: 0.086 | J11: 0.086 | K11: 0.086 | L11: FY26 = 8.6% on average total debt
A12: Tax rate (on PBT) | B12: =IF(B34-B32>0,B35/(B34-B32),0) -> 0.2426082 | C12: =IF(C34-C32>0,C35/(C34-C32),0) -> 0.30148233 | D12: =IF(D34-D32>0,D35/(D34-D32),0) -> 0.27294121 | E12: =IF(E34-E32>0,E35/(E34-E32),0) -> 0.31875649 | F12: =IF(F34-F32>0,F35/(F34-F32),0) -> 0.3079987 | G12: 0.3 | H12: 0.3 | I12: 0.3 | J12: 0.3 | K12: 0.3 | L12: Effective rate on PBT before exceptional items: FY24 27%, FY26 32%
A13: Capex — PPE (₹ cr) | B13: =Inputs!B65 -> 247.3 | C13: =Inputs!C65 -> 49.49 | D13: =Inputs!D65 -> 29.11 | E13: =Inputs!E65 -> 112.6 | F13: =Inputs!F65 -> 64.2 | G13: 80 | H13: 80 | I13: 80 | J13: 80 | K13: 80 | L13: PPE assumed flat: capex equals PPE depreciation
A14: Capex — concession assets / intangibles (₹ cr) | B14: =Inputs!B66 -> 1142.3 | C14: =Inputs!C66 -> 381.4 | D14: =Inputs!D66 -> 209.9 | E14: =Inputs!E66 -> 86.03 | F14: =Inputs!F66 -> 667.9 | G14: 700 | H14: 700 | I14: 700 | J14: 700 | K14: 700 | L14: FY26 = ₹668 cr; excludes any large new-project pipeline
A15: Net investment in long-term investments / InvIT (₹ cr) | G15: 0 | H15: 0 | I15: 0 | J15: 0 | K15: 0 | L15: Set > 0 to model equity into new projects / InvIT units
A16: New long-term borrowing (₹ cr) | G16: 500 | H16: 500 | I16: 500 | J16: 500 | K16: 500 | L16: Refinancing / drawdown; tune so cash stays ≥ 0 (see checks). FY26 repaid ₹1,443 cr and drew ₹208 cr
A17: Change in short-term borrowings (₹ cr) | G17: 0 | H17: 0 | I17: 0 | J17: 0 | K17: 0
A18: Current portion as % of closing long-term debt | B18: =B59/(B59+B61) -> 0.039485226 | C18: =C59/(C59+C61) -> 0.075076367 | D18: =D59/(D59+D61) -> 0.066982428 | E18: =E59/(E59+E61) -> 0.072067793 | F18: =F59/(F59+F61) -> 0.087177851 | G18: 0.09 | H18: 0.09 | I18: 0.09 | J18: 0.09 | K18: 0.09 | L18: FY26 = 8.7%, FY25 = 7.2%
A19: Dividend payout (% of PAT) | B19: =IF(B36>0,Inputs!B67/B36,0) -> 0 | C19: =IF(C36>0,Inputs!C67/C36,0) -> 0.091280637 | D19: =IF(D36>0,Inputs!D67/D36,0) -> 0.18041405 | E19: =IF(E36>0,Inputs!E67/E36,0) -> 0.036507711 | F19: =IF(F36>0,Inputs!F67/F36,0) -> 0.14911507 | G19: 0.15 | H19: 0.15 | I19: 0.15 | J19: 0.15 | K19: 0.15 | L19: FY26 dividends ₹127 cr = 15% of PAT
A20: Debtor days | B20: =B92 -> 95.147664 | C20: =C92 -> 131.14397 | D20: =D92 -> 64.910784 | E20: =E92 -> 47.663286 | F20: =F92 -> 51.327118 | G20: 51 | H20: 51 | I20: 51 | J20: 51 | K20: 51
A21: Inventory days | B21: =B93 -> 38.549498 | C21: =C93 -> 34.399122 | D21: =D93 -> 26.238899 | E21: =E93 -> 30.838503 | F21: =F93 -> 36.536537 | G21: 36.5 | H21: 36.5 | I21: 36.5 | J21: 36.5 | K21: 36.5
A22: Creditor days | B22: =B94 -> 46.344388 | C22: =C94 -> 57.77672 | D22: =D94 -> 60.490016 | E22: =E94 -> 47.523717 | F22: =F94 -> 25.56562 | G22: 25.6 | H22: 25.6 | I22: 25.6 | J22: 25.6 | K22: 25.6
A23: Other current assets (% of revenue) | B23: =B49/B27 -> 0.4791116 | C23: =C49/C27 -> 0.60448573 | D23: =D49/D27 -> 0.36860575 | E23: =E49/E27 -> 0.35459258 | F23: =F49/F27 -> 0.35455633 | G23: 0.355 | H23: 0.355 | I23: 0.355 | J23: 0.355 | K23: 0.355
A24: Accrued & other current liabilities (% of revenue) | B24: =B57/B27 -> 0.21984424 | C24: =C57/C27 -> 0.20406333 | D24: =D57/D27 -> 0.19361722 | E24: =E57/E27 -> 0.17588301 | F24: =F57/F27 -> 0.16834398 | G24: 0.168 | H24: 0.168 | I24: 0.168 | J24: 0.168 | K24: 0.168
A26: INCOME STATEMENT
A27: Net sales | B27: =Inputs!B15 -> 5803.7 | C27: =Inputs!C15 -> 6401.64 | D27: =Inputs!D15 -> 7409 | E27: =Inputs!E15 -> 7613.47 | F27: =Inputs!F15 -> 7648.15 | G27: =F27*(1+G7) -> 8260.002 | H27: =G27*(1+H7) -> 8920.8022 | I27: =H27*(1+I7) -> 9545.2583 | J27: =I27*(1+J7) -> 10213.426 | K27: =J27*(1+K7) -> 10826.232
A28: Operating expenditure | B28: =Inputs!B16 -> 3006.2 | C28: =Inputs!C16 -> 3172.61 | D28: =Inputs!D16 -> 4077.21 | E28: =Inputs!E16 -> 4007.62 | F28: =Inputs!F16 -> 3666.33 | G28: =G27-G29 -> 3964.801 | H28: =H27-H29 -> 4281.985 | I28: =I27-I29 -> 4581.724 | J28: =J27-J29 -> 4902.4447 | K28: =K27-K29 -> 5196.5913
A29: EBITDA | B29: =B27-B28 -> 2797.5 | C29: =C27-C28 -> 3229.03 | D29: =D27-D28 -> 3331.79 | E29: =E27-E28 -> 3605.85 | F29: =F27-F28 -> 3981.82 | G29: =G27*G8 -> 4295.201 | H29: =H27*H8 -> 4638.8171 | I29: =I27*I8 -> 4963.5343 | J29: =J27*J8 -> 5310.9817 | K29: =K27*K8 -> 5629.6406
A30: Other income | B30: =Inputs!B18 -> 551.75 | C30: =Inputs!C18 -> 301.67 | D30: =Inputs!D18 -> 792.76 | E30: =Inputs!E18 -> 418.08 | F30: =Inputs!F18 -> 205.83 | G30: =G27*G9 -> 223.02005 | H30: =H27*H9 -> 240.86166 | I30: =I27*I9 -> 257.72197 | J30: =J27*J9 -> 275.76251 | K30: =K27*K9 -> 292.30826
A31: Finance cost | B31: =Inputs!B19 -> 1890.62 | C31: =Inputs!C19 -> 1514.63 | D31: =Inputs!D19 -> 1863.32 | E31: =Inputs!E19 -> 1791.94 | F31: =Inputs!F19 -> 1755.15 | G31: =G11*AVERAGE(F43,G43) -> 1670.7624 | H31: =H11*AVERAGE(G43,H43) -> 1569.9085 | I31: =I11*AVERAGE(H43,I43) -> 1475.7661 | J31: =J11*AVERAGE(I43,J43) -> 1390.0966 | K31: =K11*AVERAGE(J43,K43) -> 1312.1373 | L31: Average-balance basis; no circularity because new borrowing is an input
A32: Exceptional items | B32: =Inputs!B20 -> 0 | C32: =Inputs!C20 -> 0 | D32: =Inputs!D20 -> 0 | E32: =Inputs!E20 -> 5804.13 | F32: =Inputs!F20 -> -42.65 | G32: 0 | H32: 0 | I32: 0 | J32: 0 | K32: 0 | L32: Assumed nil in projections
A33: Depreciation & amortisation | B33: =Inputs!B21 -> 682.77 | C33: =Inputs!C21 -> 832.12 | D33: =Inputs!D21 -> 994.95 | E33: =Inputs!E21 -> 1037.63 | F33: =Inputs!F21 -> 1142.04 | G33: =G10*(F51+F52) -> 1099.3954 | H33: =H10*(G51+G52) -> 1084.7032 | I33: =I10*(H51+H52) -> 1070.6869 | J33: =J10*(I51+I52) -> 1057.3153 | K33: =K10*(J51+J52) -> 1044.5588
A34: Profit before tax | B34: =B29+B30-B31+B32-B33 -> 775.86 | C34: =C29+C30-C31+C32-C33 -> 1183.95 | D34: =D29+D30-D31+D32-D33 -> 1266.28 | E34: =E29+E30-E31+E32-E33 -> 6998.49 | F34: =F29+F30-F31+F32-F33 -> 1247.81 | G34: =G29+G30-G31+G32-G33 -> 1748.0633 | H34: =H29+H30-H31+H32-H33 -> 2225.0671 | I34: =I29+I30-I31+I32-I33 -> 2674.8033 | ... K34: =K29+K30-K31+K32-K33 -> 3565.2528
A35: Tax | B35: =Inputs!B23 -> 188.23 | C35: =Inputs!C23 -> 356.94 | D35: =Inputs!D23 -> 345.62 | E35: =Inputs!E23 -> 380.71 | F35: =Inputs!F23 -> 397.46 | G35: =MAX(G34,0)*G12 -> 524.41898 | H35: =MAX(H34,0)*H12 -> 667.52012 | I35: =MAX(I34,0)*I12 -> 802.44099 | J35: =MAX(J34,0)*J12 -> 941.79971 | K35: =MAX(K34,0)*K12 -> 1069.5758
A36: Profit after tax | B36: =B34-B35 -> 587.63 | C36: =C34-C35 -> 827.01 | D36: =D34-D35 -> 920.66 | E36: =E34-E35 -> 6617.78 | F36: =F34-F35 -> 850.35 | G36: =G34-G35 -> 1223.6443 | H36: =H34-H35 -> 1557.547 | I36: =I34-I35 -> 1872.3623 | ... K36: =K34-K35 -> 2495.677
A38: DEBT SCHEDULE (long-term debt incl. current portion)
A39: Opening long-term debt | G39: =F59+F61 -> 19490.96 | H39: =G59+G61 -> 18291.78 | I39: =H59+H61 -> 17145.52 | J39: =I59+I61 -> 16102.423 | K39: =J59+J61 -> 15153.205
A40: Less: scheduled repayment (prior-year current portion) | G40: =F59 -> 1699.18 | H40: =G59 -> 1646.2602 | I40: =H59 -> 1543.0968 | J40: =I59 -> 1449.2181 | K40: =J59 -> 1363.7884
A41: Add: new borrowing | G41: =G16 -> 500 | H41: =H16 -> 500 | I41: =I16 -> 500 | J41: =J16 -> 500 | K41: =K16 -> 500
A42: Closing long-term debt | G42: =G39-G40+G41 -> 18291.78 | H42: =H39-H40+H41 -> 17145.52 | I42: =I39-I40+I41 -> 16102.423 | J42: =J39-J40+J41 -> 15153.205 | K42: =K39-K40+K41 -> 14289.417
A43: Total debt (incl. short-term) | B43: =B58+B59+B61 -> 16703 | C43: =C58+C59+C61 -> 16748.21 | D43: =D58+D59+D61 -> 18653.39 | E43: =E58+E59+E61 -> 20599.3 | F43: =F58+F59+F61 -> 20027.06 | G43: =G58+G59+G61 -> 18827.88 | H43: =H58+H59+H61 -> 17681.62 | I43: =I58+I59+I61 -> 16638.523 | ... K43: =K58+K59+K61 -> 14825.517
...

Sheet Sensitivity
A1: IRB Infrastructure Developers Ltd — Sensitivity Analysis (FY2027E)
A2: Live formulas (no data tables): each cell recomputes FY2027E profit, interest and the ratio from the base-case drivers below. Flexes P&L / debt drivers only; working-capital and cash effects are excluded. Blue deltas are editable.
A4: BASE CASE FY2027E (linked to Projections)
A5: Opening revenue (FY2026A) | B5: =Projections!F27 -> 7648.15
A6: Revenue growth | B6: =Projections!G7 -> 0.08
A7: EBITDA margin | B7: =Projections!G8 -> 0.52
A8: Other income (% of revenue) | B8: =Projections!G9 -> 0.027
A9: Depreciation & amortisation | B9: =Projections!G33 -> 1099.3954
A10: Interest rate | B10: =Projections!G11 -> 0.086
A11: Tax rate | B11: =Projections!G12 -> 0.3
A12: Average total debt (base) | B12: =AVERAGE(Projections!F43,Projections!G43) -> 19427.47
A13: Opening current portion of LT debt | B13: =Projections!F59 -> 1699.18
A14: Total outside liabilities (base) | B14: =Projections!G63 -> 32027.06
A15: Total equity (base) | B15: =Projections!G64 -> 21988.898
A16: Dividend payout | B16: =Projections!G19 -> 0.15
A17: Intangibles (base) | B17: =Projections!G52 -> 22634.405
A18: PAT (base) | B18: =Projections!G36 -> 1223.6443
A19: DSCR per Projections (x) | B19: =Projections!G87 -> 1.1851247
A20: ICR per Projections (x) | B20: =Projections!G91 -> 2.0462668
A21: TOL/TNW per Projections (x) | B21: =Projections!G89 -> 1.4565105
A22: Tie-out: recomputed base DSCR – Projections DSCR (should be 0.00) | B22: =(((($B$5*(1+$B$6))*$B$7+($B$5*(1+$B$6))*$B$8-$B$9-(($B$12+0/2)*($B$10+0)))-MAX((($B$5*(1+$B$6))*$B$7+($B$5*(1+$B$6))*$B$8-$B$9-(($B$12+0/2)*($B$10+0))),0)*$B$11)+$B$9+(($B$12+0/2)*($B$10+0)))/((($B$12+0/2)*($B$10+0))+$B$13)-B19 -> 0
A23: Tie-out: recomputed base TOL/TNW – Projections (should be 0.00) | B23: =IF(($B$15+(((($B$5*(1+$B$6))*$B$7+($B$5*(1+$B$6))*$B$8-$B$9-(($B$12+0/2)*($B$10+0)))-MAX((($B$5*(1+$B$6))*$B$7+($B$5*(1+$B$6))*$B$8-$B$9-(($B$12+0/2)*($B$10+0))),0)*$B$11)-$B$18)*(1-$B$16)-Inputs!$B$6*$B$17)>0,($B$14+0)/($B$15+(((($B$5*(1+$B$6))*$B$7+($B$5*(1+$B$6))*$B$8-$B$9-(($B$12+0/2)*($B$10+0)))-MAX((($B$5*(1+$B$6))*$B$7+($B$5*(1+$B$6))*$B$8-$B$9-(($B$12+0/2)*($B$10+0))),0)*$B$11)-$B$18)*(1-$B$16)-Inputs!$B$6*$B$17),"n.m.")-B21 -> 0
A25: 1. DSCR (x): revenue growth vs interest-rate change
A26: Rows: Revenue growth | Columns: Interest rate | B26: Δ vs base → | C26: -0.01 | D26: -0.005 | E26: 0 | F26: 0.005 | G26: 0.01 | H26: 0.02
B27: Level → | C27: =$B$10+C26 -> 0.076 | D27: =$B$10+D26 -> 0.081 | E27: =$B$10+E26 -> 0.086 | F27: =$B$10+F26 -> 0.091 | G27: =$B$10+G26 -> 0.096 | H27: =$B$10+H26 -> 0.106
A28: -0.15 | B28: =$B$6+A28 -> -0.07 | C28: =(((($B$5*(1+$B28))*$B$7+($B$5*(1+$B28))*$B$8-$B$9-(($B$12+0/2)*($B$10+C$26)))-MAX((($B$5*(1+$B28))*$B$7+($B$5*(1+$B28))*$B$8-$B$9-(($B$12+0/2)*($B$10+C$26))),0)*$B$11)+$B$9+(($B$12+0/2)*($B$10+C$26)))/((($B$12+0/2)*($B$10+C$26))+$B$13) -> 1.100949 | D28: =(((($B$5*(1+$B28))*$B$7+($B$5*(1+$B28))*$B$8-$B$9-(($B$12+0/2)*($B$10+D$26)))-MAX((($B$5*(1+$B28))*$B$7+($B$5*(1+$B28))*$B$8-$B$9-(($B$12+0/2)*($B$10+D$26))),0)*$B$11)+$B$9+(($B$12+0/2)*($B$10+D$26)))/((($B$12+0/2)*($B$10+D$26))+$B$13) -> 1.0771767 | E28: =(((($B$5*(1+$B28))*$B$7+($B$5*(1+$B28))*$B$8-$B$9-(($B$12+0/2)*($B$10+E$26)))-MAX((($B$5*(1+$B28))*$B$7+($B$5*(1+$B28))*$B$8-$B$9-(($B$12+0/2)*($B$10+E$26))),0)*$B$11)+$B$9+(($B$12+0/2)*($B$10+E$26)))/((($B$12+0/2)*($B$10+E$26))+$B$13) -> 1.0547749 | F28: =(((($B$5*(1+$B28))*$B$7+($B$5*(1+$B28))*$B$8-$B$9-(($B$12+0/2)*($B$10+F$26)))-MAX((($B$5*(1+$B28))*$B$7+($B$5*(1+$B28))*$B$8-$B$9-(($B$12+0/2)*($B$10+F$26))),0)*$B$11)+$B$9+(($B$12+0/2)*($B$10+F$26)))/((($B$12+0/2)*($B$10+F$26))+$B$13) -> 1.0336283 | G28: =(((($B$5*(1+$B28))*$B$7+($B$5*(1+$B28))*$B$8-$B$9-(($B$12+0/2)*($B$10+G$26)))-MAX((($B$5*(1+$B28))*$B$7+($B$5*(1+$B28))*$B$8-$B$9-(($B$12+0/2)*($B$10+G$26))),0)*$B$11)+$B$9+(($B$12+0/2)*($B$10+G$26)))/((($B$12+0/2)*($B$10+G$26))+$B$13) -> 1.0136344 | H28: =(((($B$5*(1+$B28))*$B$7+($B$5*(1+$B28))*$B$8-$B$9-(($B$12+0/2)*($B$10+H$26)))-MAX((($B$5*(1+$B28))*$B$7+($B$5*(1+$B28))*$B$8-$B$9-(($B$12+0/2)*($B$10+H$26))),0)*$B$11)+$B$9+(($B$12+0/2)*($B$10+H$26)))/((($B$12+0/2)*($B$10+H$26))+$B$13) -> 0.97674695
A29: -0.1 | B29: =$B$6+A29 -> -0.02 | C29: =(((($B$5*(1+$B29))*$B$7+($B$5*(1+$B29))*$B$8-$B$9-(($B$12+0/2)*($B$10+C$26)))-MAX((($B$5*(1+$B29))*$B$7+($B$5*(1+$B29))*$B$8-$B$9-(($B$12+0/2)*($B$10+C$26))),0)*$B$11)+$B$9+(($B$12+0/2)*($B$10+C$26)))/((($B$12+0/2)*($B$10+C$26))+$B$13) -> 1.147057 | D29: =(((($B$5*(1+$B29))*$B$7+($B$5*(1+$B29))*$B$8-$B$9-(($B$12+0/2)*($B$10+D$26)))-MAX((($B$5*(1+$B29))*$B$7+($B$5*(1+$B29))*$B$8-$B$9-(($B$12+0/2)*($B$10+D$26))),0)*$B$11)+$B$9+(($B$12+0/2)*($B$10+D$26)))/((($B$12+0/2)*($B$10+D$26))+$B$13) -> 1.1219163 | E29: =(((($B$5*(1+$B29))*$B$7+($B$5*(1+$B29))*$B$8-$B$9-(($B$12+0/2)*($B$10+E$26)))-MAX((($B$5*(1+$B29))*$B$7+($B$5*(1+$B29))*$B$8-$B$9-(($B$12+0/2)*($B$10+E$26))),0)*$B$11)+$B$9+(($B$12+0/2)*($B$10+E$26)))/((($B$12+0/2)*($B$10+E$26))+$B$13) -> 1.0982248 | F29: =(((($B$5*(1+$B29))*$B$7+($B$5*(1+$B29))*$B$8-$B$9-(($B$12+0/2)*($B$10+F$26)))-MAX((($B$5*(1+$B29))*$B$7+($B$5*(1+$B29))*$B$8-$B$9-(($B$12+0/2)*($B$10+F$26))),0)*$B$11)+$B$9+(($B$12+0/2)*($B$10+F$26)))/((($B$12+0/2)*($B$10+F$26))+$B$13) -> 1.0758609 | G29: =(((($B$5*(1+$B29))*$B$7+($B$5*(1+$B29))*$B$8-$B$9-(($B$12+0/2)*($B$10+G$26)))-MAX((($B$5*(1+$B29))*$B$7+($B$5*(1+$B29))*$B$8-$B$9-(($B$12+0/2)*($B$10+G$26))),0)*$B$11)+$B$9+(($B$12+0/2)*($B$10+G$26)))/((($B$12+0/2)*($B$10+G$26))+$B$13) -> 1.054716 | H29: =(((($B$5*(1+$B29))*$B$7+($B$5*(1+$B29))*$B$8-$B$9-(($B$12+0/2)*($B$10+H$26)))-MAX((($B$5*(1+$B29))*$B$7+($B$5*(1+$B29))*$B$8-$B$9-(($B$12+0/2)*($B$10+H$26))),0)*$B$11)+$B$9+(($B$12+0/2)*($B$10+H$26)))/((($B$12+0/2)*($B$10+H$26))+$B$13) -> 1.0157051
A30: -0.05 | B30: =$B$6+A30 -> 0.03 | C30: =(((($B$5*(1+$B30))*$B$7+($B$5*(1+$B30))*$B$8-$B$9-(($B$12+0/2)*($B$10+C$26)))-MAX((($B$5*(1+$B30))*$B$7+($B$5*(1+$B30))*$B$8-$B$9-(($B$12+0/2)*($B$10+C$26))),0)*$B$11)+$B$9+(($B$12+0/2)*($B$10+C$26)))/((($B$12+0/2)*($B$10+C$26))+$B$13) -> 1.1931651 | D30: =(((($B$5*(1+$B30))*$B$7+($B$5*(1+$B30))*$B$8-$B$9-(($B$12+0/2)*($B$10+D$26)))-MAX((($B$5*(1+$B30))*$B$7+($B$5*(1+$B30))*$B$8-$B$9-(($B$12+0/2)*($B$10+D$26))),0)*$B$11)+$B$9+(($B$12+0/2)*($B$10+D$26)))/((($B$12+0/2)*($B$10+D$26))+$B$13) -> 1.1666558 | E30: =(((($B$5*(1+$B30))*$B$7+($B$5*(1+$B30))*$B$8-$B$9-(($B$12+0/2)*($B$10+E$26)))-MAX((($B$5*(1+$B30))*$B$7+($B$5*(1+$B30))*$B$8-$B$9-(($B$12+0/2)*($B$10+E$26))),0)*$B$11)+$B$9+(($B$12+0/2)*($B$10+E$26)))/((($B$12+0/2)*($B$10+E$26))+$B$13) -> 1.1416748 | F30: =(((($B$5*(1+$B30))*$B$7+($B$5*(1+$B30))*$B$8-$B$9-(($B$12+0/2)*($B$10+F$26)))-MAX((($B$5*(1+$B30))*$B$7+($B$5*(1+$B30))*$B$8-$B$9-(($B$12+0/2)*($B$10+F$26))),0)*$B$11)+$B$9+(($B$12+0/2)*($B$10+F$26)))/((($B$12+0/2)*($B$10+F$26))+$B$13) -> 1.1180935 | G30: =(((($B$5*(1+$B30))*$B$7+($B$5*(1+$B30))*$B$8-$B$9-(($B$12+0/2)*($B$10+G$26)))-MAX((($B$5*(1+$B30))*$B$7+($B$5*(1+$B30))*$B$8-$B$9-(($B$12+0/2)*($B$10+G$26))),0)*$B$11)+$B$9+(($B$12+0/2)*($B$10+G$26)))/((($B$12+0/2)*($B$10+G$26))+$B$13) -> 1.0957976 | H30: =(((($B$5*(1+$B30))*$B$7+($B$5*(1+$B30))*$B$8-$B$9-(($B$12+0/2)*($B$10+H$26)))-MAX((($B$5*(1+$B30))*$B$7+($B$5*(1+$B30))*$B$8-$B$9-(($B$12+0/2)*($B$10+H$26))),0)*$B$11)+$B$9+(($B$12+0/2)*($B$10+H$26)))/((($B$12+0/2)*($B$10+H$26))+$B$13) -> 1.0546632
A31: 0 | B31: =$B$6+A31 -> 0.08 | C31: =(((($B$5*(1+$B31))*$B$7+($B$5*(1+$B31))*$B$8-$B$9-(($B$12+0/2)*($B$10+C$26)))-MAX((($B$5*(1+$B31))*$B$7+($B$5*(1+$B31))*$B$8-$B$9-(($B$12+0/2)*($B$10+C$26))),0)*$B$11)+$B$9+(($B$12+0/2)*($B$10+C$26)))/((($B$12+0/2)*($B$10+C$26))+$B$13) -> 1.2392731 | D31: =(((($B$5*(1+$B31))*$B$7+($B$5*(1+$B31))*$B$8-$B$9-(($B$12+0/2)*($B$10+D$26)))-MAX((($B$5*(1+$B31))*$B$7+($B$5*(1+$B31))*$B$8-$B$9-(($B$12+0/2)*($B$10+D$26))),0)*$B$11)+$B$9+(($B$12+0/2)*($B$10+D$26)))/((($B$12+0/2)*($B$10+D$26))+$B$13) -> 1.2113954 | E31: =(((($B$5*(1+$B31))*$B$7+($B$5*(1+$B31))*$B$8-$B$9-(($B$12+0/2)*($B$10+E$26)))-MAX((($B$5*(1+$B31))*$B$7+($B$5*(1+$B31))*$B$8-$B$9-(($B$12+0/2)*($B$10+E$26))),0)*$B$11)+$B$9+(($B$12+0/2)*($B$10+E$26)))/((($B$12+0/2)*($B$10+E$26))+$B$13) -> 1.1851247 | F31: =(((($B$5*(1+$B31))*$B$7+($B$5*(1+$B31))*$B$8-$B$9-(($B$12+0/2)*($B$10+F$26)))-MAX((($B$5*(1+$B31))*$B$7+($B$5*(1+$B31))*$B$8-$B$9-(($B$12+0/2)*($B$10+F$26))),0)*$B$11)+$B$9+(($B$12+0/2)*($B$10+F$26)))/((($B$12+0/2)*($B$10+F$26))+$B$13) -> 1.1603261 | G31: =(((($B$5*(1+$B31))*$B$7+($B$5*(1+$B31))*$B$8-$B$9-(($B$12+0/2)*($B$10+G$26)))-MAX((($B$5*(1+$B31))*$B$7+($B$5*(1+$B31))*$B$8-$B$9-(($B$12+0/2)*($B$10+G$26))),0)*$B$11)+$B$9+(($B$12+0/2)*($B$10+G$26)))/((($B$12+0/2)*($B$10+G$26))+$B$13) -> 1.1368793 | H31: =(((($B$5*(1+$B31))*$B$7+($B$5*(1+$B31))*$B$8-$B$9-(($B$12+0/2)*($B$10+H$26)))-MAX((($B$5*(1+$B31))*$B$7+($B$5*(1+$B31))*$B$8-$B$9-(($B$12+0/2)*($B$10+H$26))),0)*$B$11)+$B$9+(($B$12+0/2)*($B$10+H$26)))/((($B$12+0/2)*($B$10+H$26))+$B$13) -> 1.0936214
A32: 0.05 | B32: =$B$6+A32 -> 0.13 | C32: =(((($B$5*(1+$B32))*$B$7+($B$5*(1+$B32))*$B$8-$B$9-(($B$12+0/2)*($B$10+C$26)))-MAX((($B$5*(1+$B32))*$B$7+($B$5*(1+$B32))*$B$8-$B$9-(($B$12+0/2)*($B$10+C$26))),0)*$B$11)+$B$9+(($B$12+0/2)*($B$10+C$26)))/((($B$12+0/2)*($B$10+C$26))+$B$13) -> 1.2853812 | D32: =(((($B$5*(1+$B32))*$B$7+($B$5*(1+$B32))*$B$8-$B$9-(($B$12+0/2)*($B$10+D$26)))-MAX((($B$5*(1+$B32))*$B$7+($B$5*(1+$B32))*$B$8-$B$9-(($B$12+0/2)*($B$10+D$26))),0)*$B$11)+$B$9+(($B$12+0/2)*($B$10+D$26)))/((($B$12+0/2)*($B$10+D$26))+$B$13) -> 1.2561349 | E32: =(((($B$5*(1+$B32))*$B$7+($B$5*(1+$B32))*$B$8-$B$9-(($B$12+0/2)*($B$10+E$26)))-MAX((($B$5*(1+$B32))*$B$7+($B$5*(1+$B32))*$B$8-$B$9-(($B$12+0/2)*($B$10+E$26))),0)*$B$11)+$B$9+(($B$12+0/2)*($B$10+E$26)))/((($B$12+0/2)*($B$10+E$26))+$B$13) -> 1.2285747 | F32: =(((($B$5*(1+$B32))*$B$7+($B$5*(1+$B32))*$B$8-$B$9-(($B$12+0/2)*($B$10+F$26)))-MAX((($B$5*(1+$B32))*$B$7+($B$5*(1+$B32))*$B$8-$B$9-(($B$12+0/2)*($B$10+F$26))),0)*$B$11)+$B$9+(($B$12+0/2)*($B$10+F$26)))/((($B$12+0/2)*($B$10+F$26))+$B$13) -> 1.2025588 | G32: =(((($B$5*(1+$B32))*$B$7+($B$5*(1+$B32))*$B$8-$B$9-(($B$12+0/2)*($B$10+G$26)))-MAX((($B$5*(1+$B32))*$B$7+($B$5*(1+$B32))*$B$8-$B$9-(($B$12+0/2)*($B$10+G$26))),0)*$B$11)+$B$9+(($B$12+0/2)*($B$10+G$26)))/((($B$12+0/2)*($B$10+G$26))+$B$13) -> 1.1779609 | H32: =(((($B$5*(1+$B32))*$B$7+($B$5*(1+$B32))*$B$8-$B$9-(($B$12+0/2)*($B$10+H$26)))-MAX((($B$5*(1+$B32))*$B$7+($B$5*(1+$B32))*$B$8-$B$9-(($B$12+0/2)*($B$10+H$26))),0)*$B$11)+$B$9+(($B$12+0/2)*($B$10+H$26)))/((($B$12+0/2)*($B$10+H$26))+$B$13) -> 1.1325795
A33: 0.1 | B33: =$B$6+A33 -> 0.18 | C33: =(((($B$5*(1+$B33))*$B$7+($B$5*(1+$B33))*$B$8-$B$9-(($B$12+0/2)*($B$10+C$26)))-MAX((($B$5*(1+$B33))*$B$7+($B$5*(1+$B33))*$B$8-$B$9-(($B$12+0/2)*($B$10+C$26))),0)*$B$11)+$B$9+(($B$12+0/2)*($B$10+C$26)))/((($B$12+0/2)*($B$10+C$26))+$B$13) -> 1.3314892 | D33: =(((($B$5*(1+$B33))*$B$7+($B$5*(1+$B33))*$B$8-$B$9-(($B$12+0/2)*($B$10+D$26)))-MAX((($B$5*(1+$B33))*$B$7+($B$5*(1+$B33))*$B$8-$B$9-(($B$12+0/2)*($B$10+D$26))),0)*$B$11)+$B$9+(($B$12+0/2)*($B$10+D$26)))/((($B$12+0/2)*($B$10+D$26))+$B$13) -> 1.3008745 | E33: =(((($B$5*(1+$B33))*$B$7+($B$5*(1+$B33))*$B$8-$B$9-(($B$12+0/2)*($B$10+E$26)))-MAX((($B$5*(1+$B33))*$B$7+($B$5*(1+$B33))*$B$8-$B$9-(($B$12+0/2)*($B$10+E$26))),0)*$B$11)+$B$9+(($B$12+0/2)*($B$10+E$26)))/((($B$12+0/2)*($B$10+E$26))+$B$13) -> 1.2720246 | F33: =(((($B$5*(1+$B33))*$B$7+($B$5*(1+$B33))*$B$8-$B$9-(($B$12+0/2)*($B$10+F$26)))-MAX((($B$5*(1+$B33))*$B$7+($B$5*(1+$B33))*$B$8-$B$9-(($B$12+0/2)*($B$10+F$26))),0)*$B$11)+$B$9+(($B$12+0/2)*($B$10+F$26)))/((($B$12+0/2)*($B$10+F$26))+$B$13) -> 1.2447914 | G33: =(((($B$5*(1+$B33))*$B$7+($B$5*(1+$B33))*$B$8-$B$9-(($B$12+0/2)*($B$10+G$26)))-MAX((($B$5*(1+$B33))*$B$7+($B$5*(1+$B33))*$B$8-$B$9-(($B$12+0/2)*($B$10+G$26))),0)*$B$11)+$B$9+(($B$12+0/2)*($B$10+G$26)))/((($B$12+0/2)*($B$10+G$26))+$B$13) -> 1.2190425 | H33: =(((($B$5*(1+$B33))*$B$7+($B$5*(1+$B33))*$B$8-$B$9-(($B$12+0/2)*($B$10+H$26)))-MAX((($B$5*(1+$B33))*$B$7+($B$5*(1+$B33))*$B$8-$B$9-(($B$12+0/2)*($B$10+H$26))),0)*$B$11)+$B$9+(($B$12+0/2)*($B$10+H$26)))/((($B$12+0/2)*($B$10+H$26))+$B$13) -> 1.1715376
A36: 2. DSCR (x): EBITDA margin vs revenue growth
A37: Rows: EBITDA margin | Columns: Revenue growth | B37: Δ vs base → | C37: -0.15 | D37: -0.1 | E37: -0.05 | F37: 0 | G37: 0.05 | H37: 0.1
B38: Level → | C38: =$B$6+C37 -> -0.07 | D38: =$B$6+D37 -> -0.02 | E38: =$B$6+E37 -> 0.03 | F38: =$B$6+F37 -> 0.08 | G38: =$B$6+G37 -> 0.13 | H38: =$B$6+H37 -> 0.18
A39: -0.1 | B39: =$B$7+A39 -> 0.42 | C39: =(((($B$5*(1+C$38))*$B39+($B$5*(1+C$38))*$B$8-$B$9-(($B$12+0/2)*($B$10+0)))-MAX((($B$5*(1+C$38))*$B39+($B$5*(1+C$38))*$B$8-$B$9-(($B$12+0/2)*($B$10+0))),0)*$B$11)+$B$9+(($B$12+0/2)*($B$10+0)))/((($B$12+0/2)*($B$10+0))+$B$13) -> 0.90702916 | D39: =(((($B$5*(1+D$38))*$B39+($B$5*(1+D$38))*$B$8-$B$9-(($B$12+0/2)*($B$10+0)))-MAX((($B$5*(1+D$38))*$B39+($B$5*(1+D$38))*$B$8-$B$9-(($B$12+0/2)*($B$10+0))),0)*$B$11)+$B$9+(($B$12+0/2)*($B$10+0)))/((($B$12+0/2)*($B$10+0))+$B$13) -> 0.9425358 | E39: =(((($B$5*(1+E$38))*$B39+($B$5*(1+E$38))*$B$8-$B$9-(($B$12+0/2)*($B$10+0)))-MAX((($B$5*(1+E$38))*$B39+($B$5*(1+E$38))*$B$8-$B$9-(($B$12+0/2)*($B$10+0))),0)*$B$11)+$B$9+(($B$12+0/2)*($B$10+0)))/((($B$12+0/2)*($B$10+0))+$B$13) -> 0.97804243 | F39: =(((($B$5*(1+F$38))*$B39+($B$5*(1+F$38))*$B$8-$B$9-(($B$12+0/2)*($B$10+0)))-MAX((($B$5*(1+F$38))*$B39+($B$5*(1+F$38))*$B$8-$B$9-(($B$12+0/2)*($B$10+0))),0)*$B$11)+$B$9+(($B$12+0/2)*($B$10+0)))/((($B$12+0/2)*($B$10+0))+$B$13) -> 1.0135491 | G39: =(((($B$5*(1+G$38))*$B39+($B$5*(1+G$38))*$B$8-$B$9-(($B$12+0/2)*($B$10+0)))-MAX((($B$5*(1+G$38))*$B39+($B$5*(1+G$38))*$B$8-$B$9-(($B$12+0/2)*($B$10+0))),0)*$B$11)+$B$9+(($B$12+0/2)*($B$10+0)))/((($B$12+0/2)*($B$10+0))+$B$13) -> 1.0490557 | H39: =(((($B$5*(1+H$38))*$B39+($B$5*(1+H$38))*$B$8-$B$9-(($B$12+0/2)*($B$10+0)))-MAX((($B$5*(1+H$38))*$B39+($B$5*(1+H$38))*$B$8-$B$9-(($B$12+0/2)*($B$10+0))),0)*$B$11)+$B$9+(($B$12+0/2)*($B$10+0)))/((($B$12+0/2)*($B$10+0))+$B$13) -> 1.0845623
A40: -0.05 | B40: =$B$7+A40 -> 0.47 | C40: =(((($B$5*(1+C$38))*$B40+($B$5*(1+C$38))*$B$8-$B$9-(($B$12+0/2)*($B$10+0)))-MAX((($B$5*(1+C$38))*$B40+($B$5*(1+C$38))*$B$8-$B$9-(($B$12+0/2)*($B$10+0))),0)*$B$11)+$B$9+(($B$12+0/2)*($B$10+0)))/((($B$12+0/2)*($B$10+0))+$B$13) -> 0.98090202 | D40: =(((($B$5*(1+D$38))*$B40+($B$5*(1+D$38))*$B$8-$B$9-(($B$12+0/2)*($B$10+0)))-MAX((($B$5*(1+D$38))*$B40+($B$5*(1+D$38))*$B$8-$B$9-(($B$12+0/2)*($B$10+0))),0)*$B$11)+$B$9+(($B$12+0/2)*($B$10+0)))/((($B$12+0/2)*($B$10+0))+$B$13) -> 1.0203803 | E40: =(((($B$5*(1+E$38))*$B40+($B$5*(1+E$38))*$B$8-$B$9-(($B$12+0/2)*($B$10+0)))-MAX((($B$5*(1+E$38))*$B40+($B$5*(1+E$38))*$B$8-$B$9-(($B$12+0/2)*($B$10+0))),0)*$B$11)+$B$9+(($B$12+0/2)*($B$10+0)))/((($B$12+0/2)*($B$10+0))+$B$13) -> 1.0598586 | F40: =(((($B$5*(1+F$38))*$B40+($B$5*(1+F$38))*$B$8-$B$9-(($B$12+0/2)*($B$10+0)))-MAX((($B$5*(1+F$38))*$B40+($B$5*(1+F$38))*$B$8-$B$9-(($B$12+0/2)*($B$10+0))),0)*$B$11)+$B$9+(($B$12+0/2)*($B$10+0)))/((($B$12+0/2)*($B$10+0))+$B$13) -> 1.0993369 | G40: =(((($B$5*(1+G$38))*$B40+($B$5*(1+G$38))*$B$8-$B$9-(($B$12+0/2)*($B$10+0)))-MAX((($B$5*(1+G$38))*$B40+($B$5*(1+G$38))*$B$8-$B$9-(($B$12+0/2)*($B$10+0))),0)*$B$11)+$B$9+(($B$12+0/2)*($B$10+0)))/((($B$12+0/2)*($B$10+0))+$B$13) -> 1.1388152 | H40: =(((($B$5*(1+H$38))*$B40+($B$5*(1+H$38))*$B$8-$B$9-(($B$12+0/2)*($B$10+0)))-MAX((($B$5*(1+H$38))*$B40+($B$5*(1+H$38))*$B$8-$B$9-(($B$12+0/2)*($B$10+0))),0)*$B$11)+$B$9+(($B$12+0/2)*($B$10+0)))/((($B$12+0/2)*($B$10+0))+$B$13) -> 1.1782935
A41: -0.025 | B41: =$B$7+A41 -> 0.495 | C41: =(((($B$5*(1+C$38))*$B41+($B$5*(1+C$38))*$B$8-$B$9-(($B$12+0/2)*($B$10+0)))-MAX((($B$5*(1+C$38))*$B41+($B$5*(1+C$38))*$B$8-$B$9-(($B$12+0/2)*($B$10+0))),0)*$B$11)+$B$9+(($B$12+0/2)*($B$10+0)))/((($B$12+0/2)*($B$10+0))+$B$13) -> 1.0178385 | D41: =(((($B$5*(1+D$38))*$B41+($B$5*(1+D$38))*$B$8-$B$9-(($B$12+0/2)*($B$10+0)))-MAX((($B$5*(1+D$38))*$B41+($B$5*(1+D$38))*$B$8-$B$9-(($B$12+0/2)*($B$10+0))),0)*$B$11)+$B$9+(($B$12+0/2)*($B$10+0)))/((($B$12+0/2)*($B$10+0))+$B$13) -> 1.0593026 | E41: =(((($B$5*(1+E$38))*$B41+($B$5*(1+E$38))*$B$8-$B$9-(($B$12+0/2)*($B$10+0)))-MAX((($B$5*(1+E$38))*$B41+($B$5*(1+E$38))*$B$8-$B$9-(($B$12+0/2)*($B$10+0))),0)*$B$11)+$B$9+(($B$12+0/2)*($B$10+0)))/((($B$12+0/2)*($B$10+0))+$B$13) -> 1.1007667 | F41: =(((($B$5*(1+F$38))*$B41+($B$5*(1+F$38))*$B$8-$B$9-(($B$12+0/2)*($B$10+0)))-MAX((($B$5*(1+F$38))*$B41+($B$5*(1+F$38))*$B$8-$B$9-(($B$12+0/2)*($B$10+0))),0)*$B$11)+$B$9+(($B$12+0/2)*($B$10+0)))/((($B$12+0/2)*($B$10+0))+$B$13) -> 1.1422308 | G41: =(((($B$5*(1+G$38))*$B41+($B$5*(1+G$38))*$B$8-$B$9-(($B$12+0/2)*($B$10+0)))-MAX((($B$5*(1+G$38))*$B41+($B$5*(1+G$38))*$B$8-$B$9-(($B$12+0/2)*($B$10+0))),0)*$B$11)+$B$9+(($B$12+0/2)*($B$10+0)))/((($B$12+0/2)*($B$10+0))+$B$13) -> 1.1836949 | H41: =(((($B$5*(1+H$38))*$B41+($B$5*(1+H$38))*$B$8-$B$9-(($B$12+0/2)*($B$10+0)))-MAX((($B$5*(1+H$38))*$B41+($B$5*(1+H$38))*$B$8-$B$9-(($B$12+0/2)*($B$10+0))),0)*$B$11)+$B$9+(($B$12+0/2)*($B$10+0)))/((($B$12+0/2)*($B$10+0))+$B$13) -> 1.2251591
A42: 0 | B42: =$B$7+A42 -> 0.52 | C42: =(((($B$5*(1+C$38))*$B42+($B$5*(1+C$38))*$B$8-$B$9-(($B$12+0/2)*($B$10+0)))-MAX((($B$5*(1+C$38))*$B42+($B$5*(1+C$38))*$B$8-$B$9-(($B$12+0/2)*($B$10+0))),0)*$B$11)+$B$9+(($B$12+0/2)*($B$10+0)))/((($B$12+0/2)*($B$10+0))+$B$13) -> 1.0547749 | D42: =(((($B$5*(1+D$38))*$B42+($B$5*(1+D$38))*$B$8-$B$9-(($B$12+0/2)*($B$10+0)))-MAX((($B$5*(1+D$38))*$B42+($B$5*(1+D$38))*$B$8-$B$9-(($B$12+0/2)*($B$10+0))),0)*$B$11)+$B$9+(($B$12+0/2)*($B$10+0)))/((($B$12+0/2)*($B$10+0))+$B$13) -> 1.0982248 | E42: =(((($B$5*(1+E$38))*$B42+($B$5*(1+E$38))*$B$8-$B$9-(($B$12+0/2)*($B$10+0)))-MAX((($B$5*(1+E$38))*$B42+($B$5*(1+E$38))*$B$8-$B$9-(($B$12+0/2)*($B$10+0))),0)*$B$11)+$B$9+(($B$12+0/2)*($B$10+0)))/((($B$12+0/2)*($B$10+0))+$B$13) -> 1.1416748 | F42: =(((($B$5*(1+F$38))*$B42+($B$5*(1+F$38))*$B$8-$B$9-(($B$12+0/2)*($B$10+0)))-MAX((($B$5*(1+F$38))*$B42+($B$5*(1+F$38))*$B$8-$B$9-(($B$12+0/2)*($B$10+0))),0)*$B$11)+$B$9+(($B$12+0/2)*($B$10+0)))/((($B$12+0/2)*($B$10+0))+$B$13) -> 1.1851247 | G42: =(((($B$5*(1+G$38))*$B42+($B$5*(1+G$38))*$B$8-$B$9-(($B$12+0/2)*($B$10+0)))-MAX((($B$5*(1+G$38))*$B42+($B$5*(1+G$38))*$B$8-$B$9-(($B$12+0/2)*($B$10+0))),0)*$B$11)+$B$9+(($B$12+0/2)*($B$10+0)))/((($B$12+0/2)*($B$10+0))+$B$13) -> 1.2285747 | H42: =(((($B$5*(1+H$38))*$B42+($B$5*(1+H$38))*$B$8-$B$9-(($B$12+0/2)*($B$10+0)))-MAX((($B$5*(1+H$38))*$B42+($B$5*(1+H$38))*$B$8-$B$9-(($B$12+0/2)*($B$10+0))),0)*$B$11)+$B$9+(($B$12+0/2)*($B$10+0)))/((($B$12+0/2)*($B$10+0))+$B$13) -> 1.2720246
A43: 0.025 | B43: =$B$7+A43 -> 0.545 | C43: =(((($B$5*(1+C$38))*$B43+($B$5*(1+C$38))*$B$8-$B$9-(($B$12+0/2)*($B$10+0)))-MAX((($B$5*(1+C$38))*$B43+($B$5*(1+C$38))*$B$8-$B$9-(($B$12+0/2)*($B$10+0))),0)*$B$11)+$B$9+(($B$12+0/2)*($B$10+0)))/((($B$12+0/2)*($B$10+0))+$B$13) -> 1.0917113 | D43: =(((($B$5*(1+D$38))*$B43+($B$5*(1+D$38))*$B$8-$B$9-(($B$12+0/2)*($B$10+0)))-MAX((($B$5*(1+D$38))*$B43+($B$5*(1+D$38))*$B$8-$B$9-(($B$12+0/2)*($B$10+0))),0)*$B$11)+$B$9+(($B$12+0/2)*($B$10+0)))/((($B$12+0/2)*($B$10+0))+$B$13) -> 1.1371471 | E43: =(((($B$5*(1+E$38))*$B43+($B$5*(1+E$38))*$B$8-$B$9-(($B$12+0/2)*($B$10+0)))-MAX((($B$5*(1+E$38))*$B43+($B$5*(1+E$38))*$B$8-$B$9-(($B$12+0/2)*($B$10+0))),0)*$B$11)+$B$9+(($B$12+0/2)*($B$10+0)))/((($B$12+0/2)*($B$10+0))+$B$13) -> 1.1825829 | F43: =(((($B$5*(1+F$38))*$B43+($B$5*(1+F$38))*$B$8-$B$9-(($B$12+0/2)*($B$10+0)))-MAX((($B$5*(1+F$38))*$B43+($B$5*(1+F$38))*$B$8-$B$9-(($B$12+0/2)*($B$10+0))),0)*$B$11)+$B$9+(($B$12+0/2)*($B$10+0)))/((($B$12+0/2)*($B$10+0))+$B$13) -> 1.2280187 | G43: =(((($B$5*(1+G$38))*$B43+($B$5*(1+G$38))*$B$8-$B$9-(($B$12+0/2)*($B$10+0)))-MAX((($B$5*(1+G$38))*$B43+($B$5*(1+G$38))*$B$8-$B$9-(($B$12+0/2)*($B$10+0))),0)*$B$11)+$B$9+(($B$12+0/2)*($B$10+0)))/((($B$12+0/2)*($B$10+0))+$B$13) -> 1.2734544 | H43: =(((($B$5*(1+H$38))*$B43+($B$5*(1+H$38))*$B$8-$B$9-(($B$12+0/2)*($B$10+0)))-MAX((($B$5*(1+H$38))*$B43+($B$5*(1+H$38))*$B$8-$B$9-(($B$12+0/2)*($B$10+0))),0)*$B$11)+$B$9+(($B$12+0/2)*($B$10+0)))/((($B$12+0/2)*($B$10+0))+$B$13) -> 1.3188902
A44: 0.05 | B44: =$B$7+A44 -> 0.57 | C44: =(((($B$5*(1+C$38))*$B44+($B$5*(1+C$38))*$B$8-$B$9-(($B$12+0/2)*($B$10+0)))-MAX((($B$5*(1+C$38))*$B44+($B$5*(1+C$38))*$B$8-$B$9-(($B$12+0/2)*($B$10+0))),0)*$B$11)+$B$9+(($B$12+0/2)*($B$10+0)))/((($B$12+0/2)*($B$10+0))+$B$13) -> 1.1286477 | D44: =(((($B$5*(1+D$38))*$B44+($B$5*(1+D$38))*$B$8-$B$9-(($B$12+0/2)*($B$10+0)))-MAX((($B$5*(1+D$38))*$B44+($B$5*(1+D$38))*$B$8-$B$9-(($B$12+0/2)*($B$10+0))),0)*$B$11)+$B$9+(($B$12+0/2)*($B$10+0)))/((($B$12+0/2)*($B$10+0))+$B$13) -> 1.1760694 | E44: =(((($B$5*(1+E$38))*$B44+($B$5*(1+E$38))*$B$8-$B$9-(($B$12+0/2)*($B$10+0)))-MAX((($B$5*(1+E$38))*$B44+($B$5*(1+E$38))*$B$8-$B$9-(($B$12+0/2)*($B$10+0))),0)*$B$11)+$B$9+(($B$12+0/2)*($B$10+0)))/((($B$12+0/2)*($B$10+0))+$B$13) -> 1.223491 | F44: =(((($B$5*(1+F$38))*$B44+($B$5*(1+F$38))*$B$8-$B$9-(($B$12+0/2)*($B$10+0)))-MAX((($B$5*(1+F$38))*$B44+($B$5*(1+F$38))*$B$8-$B$9-(($B$12+0/2)*($B$10+0))),0)*$B$11)+$B$9+(($B$12+0/2)*($B$10+0)))/((($B$12+0/2)*($B$10+0))+$B$13) -> 1.2709126 | G44: =(((($B$5*(1+G$38))*$B44+($B$5*(1+G$38))*$B$8-$B$9-(($B$12+0/2)*($B$10+0)))-MAX((($B$5*(1+G$38))*$B44+($B$5*(1+G$38))*$B$8-$B$9-(($B$12+0/2)*($B$10+0))),0)*$B$11)+$B$9+(($B$12+0/2)*($B$10+0)))/((($B$12+0/2)*($B$10+0))+$B$13) -> 1.3183342 | H44: =(((($B$5*(1+H$38))*$B44+($B$5*(1+H$38))*$B$8-$B$9-(($B$12+0/2)*($B$10+0)))-MAX((($B$5*(1+H$38))*$B44+($B$5*(1+H$38))*$B$8-$B$9-(($B$12+0/2)*($B$10+0))),0)*$B$11)+$B$9+(($B$12+0/2)*($B$10+0)))/((($B$12+0/2)*($B$10+0))+$B$13) -> 1.3657558
...
